# 异常
当检测到一个错误时,Python解释器就无法执行了,反而出现了一些错误提示,这就是所谓的"异常",也就是常说的BUG.

# 捕获异常
```
try:
    print(name)
except NameError as e:
    print("出现了变量未定义的异常")
    print(e)
```
输出结果:
```
出现了变量未定义的异常
name 'name' is not defined
```